2021-05-16 19:37:49,440 - root - INFO - Bot server started
2021-05-16 19:37:49,967 - root - INFO - Successfully initialized handlers
2021-05-16 19:39:11,915 - root - INFO - Bot server started
2021-05-16 19:39:12,189 - root - INFO - Successfully initialized handlers
2021-05-16 19:39:48,499 - root - INFO - Bot server started
2021-05-16 19:39:48,658 - root - INFO - Successfully initialized handlers
2021-05-16 19:39:48,659 - apscheduler.scheduler - INFO - Scheduler started
2021-05-16 19:39:52,887 - telegram.ext.dispatcher - ERROR - No error handlers are registered, logging exception.
Traceback (most recent call last):
  File "/home/monora/Git/warehousebot/env/lib/python3.8/site-packages/telegram/ext/dispatcher.py", line 447, in process_update
    handler.handle_update(update, self, check, context)
  File "/home/monora/Git/warehousebot/env/lib/python3.8/site-packages/telegram/ext/handler.py", line 160, in handle_update
    return self.callback(update, context)
TypeError: 'NoneType' object is not callable
2021-05-16 19:39:55,343 - telegram.ext.dispatcher - ERROR - No error handlers are registered, logging exception.
Traceback (most recent call last):
  File "/home/monora/Git/warehousebot/env/lib/python3.8/site-packages/telegram/ext/dispatcher.py", line 447, in process_update
    handler.handle_update(update, self, check, context)
  File "/home/monora/Git/warehousebot/env/lib/python3.8/site-packages/telegram/ext/handler.py", line 160, in handle_update
    return self.callback(update, context)
TypeError: 'NoneType' object is not callable
2021-05-16 19:39:57,352 - telegram.ext.dispatcher - ERROR - No error handlers are registered, logging exception.
Traceback (most recent call last):
  File "/home/monora/Git/warehousebot/env/lib/python3.8/site-packages/telegram/ext/dispatcher.py", line 447, in process_update
    handler.handle_update(update, self, check, context)
  File "/home/monora/Git/warehousebot/env/lib/python3.8/site-packages/telegram/ext/handler.py", line 160, in handle_update
    return self.callback(update, context)
TypeError: 'NoneType' object is not callable
2021-05-16 19:39:58,297 - telegram.ext.dispatcher - ERROR - No error handlers are registered, logging exception.
Traceback (most recent call last):
  File "/home/monora/Git/warehousebot/env/lib/python3.8/site-packages/telegram/ext/dispatcher.py", line 447, in process_update
    handler.handle_update(update, self, check, context)
  File "/home/monora/Git/warehousebot/env/lib/python3.8/site-packages/telegram/ext/handler.py", line 160, in handle_update
    return self.callback(update, context)
TypeError: 'NoneType' object is not callable
2021-05-16 19:40:14,664 - telegram.ext.updater - INFO - Received signal 2 (SIGINT), stopping...
2021-05-16 19:40:14,664 - apscheduler.scheduler - INFO - Scheduler has been shut down
2021-05-16 19:40:14,852 - telegram.ext.updater - WARNING - Exiting immediately!
2021-05-16 19:40:16,971 - root - INFO - Bot server started
2021-05-16 19:40:17,368 - root - INFO - Successfully initialized handlers
2021-05-16 19:40:17,369 - apscheduler.scheduler - INFO - Scheduler started
2021-05-16 19:40:23,450 - telegram.ext.dispatcher - ERROR - No error handlers are registered, logging exception.
Traceback (most recent call last):
  File "/home/monora/Git/warehousebot/env/lib/python3.8/site-packages/telegram/ext/dispatcher.py", line 447, in process_update
    handler.handle_update(update, self, check, context)
  File "/home/monora/Git/warehousebot/env/lib/python3.8/site-packages/telegram/ext/handler.py", line 160, in handle_update
    return self.callback(update, context)
TypeError: 'NoneType' object is not callable
2021-05-16 19:40:25,750 - telegram.ext.dispatcher - ERROR - No error handlers are registered, logging exception.
Traceback (most recent call last):
  File "/home/monora/Git/warehousebot/env/lib/python3.8/site-packages/telegram/ext/dispatcher.py", line 447, in process_update
    handler.handle_update(update, self, check, context)
  File "/home/monora/Git/warehousebot/env/lib/python3.8/site-packages/telegram/ext/handler.py", line 160, in handle_update
    return self.callback(update, context)
TypeError: 'NoneType' object is not callable
2021-05-16 19:41:26,474 - telegram.ext.updater - INFO - Received signal 2 (SIGINT), stopping...
2021-05-16 19:41:26,474 - apscheduler.scheduler - INFO - Scheduler has been shut down
2021-05-16 19:41:26,659 - telegram.ext.updater - WARNING - Exiting immediately!
2021-05-16 19:41:31,833 - root - INFO - Bot server started
2021-05-16 19:41:32,063 - root - INFO - Successfully initialized handlers
2021-05-16 19:41:32,064 - apscheduler.scheduler - INFO - Scheduler started
2021-05-16 19:41:35,108 - telegram.ext.dispatcher - ERROR - No error handlers are registered, logging exception.
Traceback (most recent call last):
  File "/home/monora/Git/warehousebot/env/lib/python3.8/site-packages/telegram/ext/dispatcher.py", line 447, in process_update
    handler.handle_update(update, self, check, context)
  File "/home/monora/Git/warehousebot/env/lib/python3.8/site-packages/telegram/ext/handler.py", line 160, in handle_update
    return self.callback(update, context)
TypeError: 'NoneType' object is not callable
2021-05-16 19:41:36,600 - telegram.ext.dispatcher - ERROR - No error handlers are registered, logging exception.
Traceback (most recent call last):
  File "/home/monora/Git/warehousebot/env/lib/python3.8/site-packages/telegram/ext/dispatcher.py", line 447, in process_update
    handler.handle_update(update, self, check, context)
  File "/home/monora/Git/warehousebot/env/lib/python3.8/site-packages/telegram/ext/handler.py", line 160, in handle_update
    return self.callback(update, context)
TypeError: 'NoneType' object is not callable
2021-05-16 19:41:37,724 - telegram.ext.dispatcher - ERROR - No error handlers are registered, logging exception.
Traceback (most recent call last):
  File "/home/monora/Git/warehousebot/env/lib/python3.8/site-packages/telegram/ext/dispatcher.py", line 447, in process_update
    handler.handle_update(update, self, check, context)
  File "/home/monora/Git/warehousebot/env/lib/python3.8/site-packages/telegram/ext/handler.py", line 160, in handle_update
    return self.callback(update, context)
TypeError: 'NoneType' object is not callable
2021-05-16 19:41:52,240 - telegram.ext.updater - INFO - Received signal 2 (SIGINT), stopping...
2021-05-16 19:41:52,240 - apscheduler.scheduler - INFO - Scheduler has been shut down
2021-05-16 19:41:52,459 - telegram.ext.updater - WARNING - Exiting immediately!
